Workbook

Sheet Cost Breakdown
A1: category | B1: Menu Item | C1: Component | D1: Ingredient | E1: Amount per Portion | F1: Portion Unit | G1: Wholesale Price (per Base Unit) | H1: Cost per Portion Amount | I1: Subtotal per Component | J1: Cost per Menu Item | K1: Menu Price
A2: entrée | B2: Chicken Biscuit | C2: Biscuit | D2: Flour | E2: 0.25 | F2: cup | G2: $0.60/lb | H2: 0.04 | I2: =SUM(H2:H6) -> 0.39 | J2: =$I$19 -> 2.34 | K2: =CEILING(($J$2*3),0.5) -> 7.5
A3: entrée | B3: Chicken Biscuit | C3: Biscuit | D3: Baking Powder | E3: 0.13 | F3: tbsp | G3: $4.50/lb | H3: 0.01 | J3: =$I$19 -> 2.34 | K3: =CEILING((J3*3),0.5) -> 7.5
A4: entrée | B4: Chicken Biscuit | C4: Biscuit | D4: Salt | E4: 0.13 | F4: tbsp | G4: $0.75/lb | H4: 0 | J4: =$I$19 -> 2.34 | K4: =CEILING((J4*3),0.5) -> 7.5
A5: entrée | B5: Chicken Biscuit | C5: Biscuit | D5: Butter | E5: 1 | F5: tbsp | G5: $2.55/lb | H5: 0.08 | J5: =$I$19 -> 2.34 | K5: =CEILING((J5*3),0.5) -> 7.5
A6: entrée | B6: Chicken Biscuit | C6: Biscuit | D6: Buttermilk | E6: 0.13 | F6: cup | G6: $4.00/gal | H6: 0.26 | J6: =$I$19 -> 2.34 | K6: =CEILING((J6*3),0.5) -> 7.5
A7: entrée | B7: Chicken Biscuit | C7: Fried Chicken Cutlet | D7: Chicken Breast | E7: 0.5 | F7: lb | G7: $3.00/lb | H7: 1.5 | I7: =SUM(H7:H18) -> 1.95 | J7: =$I$19 -> 2.34 | K7: =CEILING((J7*3),0.5) -> 7.5
A8: entrée | B8: Chicken Biscuit | C8: Fried Chicken Cutlet | D8: Dill Pickle Juice | E8: 0.25 | F8: cup | G8: $5.00/gal | H8: 0.1 | J8: =$I$19 -> 2.34 | K8: =CEILING((J8*3),0.5) -> 7.5
A9: entrée | B9: Chicken Biscuit | C9: Fried Chicken Cutlet | D9: Egg | E9: 0.25 | F9: egg | G9: $0.21/egg | H9: 0.05 | J9: =$I$19 -> 2.34 | K9: =CEILING((J9*3),0.5) -> 7.5
A10: entrée | B10: Chicken Biscuit | C10: Fried Chicken Cutlet | D10: Whole Milk | E10: 0.13 | F10: cup | G10: $2.75/gal | H10: 0.09 | J10: =$I$19 -> 2.34 | K10: =CEILING((J10*3),0.5) -> 7.5
A11: entrée | B11: Chicken Biscuit | C11: Fried Chicken Cutlet | D11: Franks Red Hot | E11: 0.25 | F11: tbsp | G11: $13.50/gal | H11: 0.03 | J11: =$I$19 -> 2.34 | K11: =CEILING((J11*3),0.5) -> 7.5
A12: entrée | B12: Chicken Biscuit | C12: Fried Chicken Cutlet | D12: Flour | E12: 0.25 | F12: cup | G12: $0.60/lb | H12: 0.04 | J12: =$I$19 -> 2.34 | K12: =CEILING((J12*3),0.5) -> 7.5
A13: entrée | B13: Chicken Biscuit | C13: Fried Chicken Cutlet | D13: Powdered Sugar | E13: 0.5 | F13: tbsp | G13: $0.75/lb | H13: 0.01 | J13: =$I$19 -> 2.34 | K13: =CEILING((J13*3),0.5) -> 7.5
A14: entrée | B14: Chicken Biscuit | C14: Fried Chicken Cutlet | D14: Paprika | E14: 0.25 | F14: tbsp | G14: $7.00/lb | H14: 0.04 | J14: =$I$19 -> 2.34 | K14: =CEILING((J14*3),0.5) -> 7.5
A15: entrée | B15: Chicken Biscuit | C15: Fried Chicken Cutlet | D15: Salt | E15: 0.25 | F15: tbsp | G15: $0.75/lb | H15: 0 | J15: =$I$19 -> 2.34 | K15: =CEILING((J15*3),0.5) -> 7.5
A16: entrée | B16: Chicken Biscuit | C16: Fried Chicken Cutlet | D16: Black Pepper | E16: 0.25 | F16: tbsp | G16: $8.00/lb | H16: 0.05 | J16: =$I$19 -> 2.34 | K16: =CEILING((J16*3),0.5) -> 7.5
A17: entrée | B17: Chicken Biscuit | C17: Fried Chicken Cutlet | D17: Garlic Salt | E17: 0.25 | F17: tbsp | G17: $5.25/lb | H17: 0.04 | J17: =$I$19 -> 2.34 | K17: =CEILING((J17*3),0.5) -> 7.5
A18: entrée | B18: Chicken Biscuit | C18: Fried Chicken Cutlet | D18: Frying Oil | F18: - | G18: Negligible | H18: 0 | J18: =$I$19 -> 2.34 | K18: =CEILING((J18*3),0.5) -> 7.5
A19: entrée | B19: Total per Chicken Biscuit Portion | C19: - | D19: - | F19: - | G19: - | I19: =SUM(I2:I18) -> 2.34 | J19: =$I$19 -> 2.34 | K19: =CEILING((J19*3),0.5) -> 7.5
A20: entrée | B20: Biscuits n Chicken Gravy | C20: Biscuit | D20: Flour | E20: 0.25 | F20: cup | G20: $0.60/lb | H20: 0.04 | I20: =SUM(H20:H24) -> 0.39 | J20: =$I$32 -> 1.19 | K20: =CEILING(($J$20*3),0.5) -> 4
A21: entrée | B21: Biscuits n Chicken Gravy | C21: Biscuit | D21: Baking Powder | E21: 0.13 | F21: tbsp | G21: $4.50/lb | H21: 0.01 | J21: =$I$32 -> 1.19 | K21: =CEILING((J21*3),0.5) -> 4
A22: entrée | B22: Biscuits n Chicken Gravy | C22: Biscuit | D22: Salt | E22: 0.13 | F22: tbsp | G22: $0.75/lb | H22: 0 | J22: =$I$32 -> 1.19 | K22: =CEILING((J22*3),0.5) -> 4
A23: entrée | B23: Biscuits n Chicken Gravy | C23: Biscuit | D23: Butter | E23: 1 | F23: tbsp | G23: $2.55/lb | H23: 0.08 | J23: =$I$32 -> 1.19 | K23: =CEILING((J23*3),0.5) -> 4
A24: entrée | B24: Biscuits n Chicken Gravy | C24: Biscuit | D24: Buttermilk | E24: 0.13 | F24: cup | G24: $4.00/gal | H24: 0.26 | J24: =$I$32 -> 1.19 | K24: =CEILING((J24*3),0.5) -> 4
A25: entrée | B25: Biscuits n Chicken Gravy | C25: Chicken Gravy | D25: Chicken Drippings | E25: 2 | F25: tbsp | G25: $0.00 (byproduct) | H25: 0 | I25: =SUM(H25:H31) -> 0.8 | J25: =$I$32 -> 1.19 | K25: =CEILING((J25*3),0.5) -> 4
A26: entrée | B26: Biscuits n Chicken Gravy | C26: Chicken Gravy | D26: Butter | E26: 2 | F26: tbsp | G26: $2.55/lb | H26: 0.16 | J26: =$I$32 -> 1.19 | K26: =CEILING((J26*3),0.5) -> 4
A27: entrée | B27: Biscuits n Chicken Gravy | C27: Chicken Gravy | D27: Flour | E27: 0.25 | F27: cup | G27: $0.60/lb | H27: 0.04 | J27: =$I$32 -> 1.19 | K27: =CEILING((J27*3),0.5) -> 4
A28: entrée | B28: Biscuits n Chicken Gravy | C28: Chicken Gravy | D28: Whole Milk | E28: 2 | F28: cup | G28: $2.75/gal | H28: 0.34 | J28: =$I$32 -> 1.19 | K28: =CEILING((J28*3),0.5) -> 4
A29: entrée | B29: Biscuits n Chicken Gravy | C29: Chicken Gravy | D29: Salt | E29: 1 | F29: tbsp | G29: $0.75/lb | H29: 0.02 | J29: =$I$32 -> 1.19 | K29: =CEILING((J29*3),0.5) -> 4
A30: entrée | B30: Biscuits n Chicken Gravy | C30: Chicken Gravy | D30: Black Pepper | E30: 1 | F30: tbsp | G30: $8.00/lb | H30: 0.2 | J30: =$I$32 -> 1.19 | K30: =CEILING((J30*3),0.5) -> 4
A31: entrée | B31: Biscuits n Chicken Gravy | C31: Chicken Gravy | D31: Chicken Boullion | E31: 1 | F31: tsp | G31: $6.00/lb | H31: 0.04 | J31: =$I$32 -> 1.19 | K31: =CEILING((J31*3),0.5) -> 4
A32: entrée | B32: Total per Biscuits n Chicken Gravy Portion | C32: - | D32: - | F32: - | G32: - | I32: =SUM(I20:I31) -> 1.19 | J32: =$I$32 -> 1.19 | K32: =CEILING((J32*3),0.5) -> 4
A33: entrée | B33: 4 pc Tenders | C33: Fried Chicken Tenderloins | D33: Chicken Breast | E33: 0.5 | F33: lb | G33: $3.00/lb | H33: 1.5 | I33: =SUM(H33:H44) -> 1.95 | J33: =$I$45 -> 1.95 | K33: =CEILING(($J$33*3),0.5) -> 6
A34: entrée | B34: 4 pc Tenders | C34: Fried Chicken Tenderloins | D34: Dill Pickle Juice | E34: 0.25 | F34: cup | G34: $5.00/gal | H34: 0.1 | J34: =$I$45 -> 1.95 | K34: =CEILING((J34*3),0.5) -> 6
A35: entrée | B35: 4 pc Tenders | C35: Fried Chicken Tenderloins | D35: Egg | E35: 0.25 | F35: egg | G35: $0.21/egg | H35: 0.05 | J35: =$I$45 -> 1.95 | K35: =CEILING((J35*3),0.5) -> 6
A36: entrée | B36: 4 pc Tenders | C36: Fried Chicken Tenderloins | D36: Whole Milk | E36: 0.13 | F36: cup | G36: $2.75/gal | H36: 0.09 | J36: =$I$45 -> 1.95 | K36: =CEILING((J36*3),0.5) -> 6
A37: entrée | B37: 4 pc Tenders | C37: Fried Chicken Tenderloins | D37: Franks Red Hot | E37: 0.25 | F37: tbsp | G37: $13.50/gal | H37: 0.03 | J37: =$I$45 -> 1.95 | K37: =CEILING((J37*3),0.5) -> 6
A38: entrée | B38: 4 pc Tenders | C38: Fried Chicken Tenderloins | D38: Flour | E38: 0.25 | F38: cup | G38: $0.60/lb | H38: 0.04 | J38: =$I$45 -> 1.95 | K38: =CEILING((J38*3),0.5) -> 6
A39: entrée | B39: 4 pc Tenders | C39: Fried Chicken Tenderloins | D39: Powdered Sugar | E39: 0.5 | F39: tbsp | G39: $0.75/lb | H39: 0.01 | J39: =$I$45 -> 1.95 | K39: =CEILING((J39*3),0.5) -> 6
A40: entrée | B40: 4 pc Tenders | C40: Fried Chicken Tenderloins | D40: Paprika | E40: 0.25 | F40: tbsp | G40: $7.00/lb | H40: 0.04 | J40: =$I$45 -> 1.95 | K40: =CEILING((J40*3),0.5) -> 6
...

Sheet avg menu prices
A1: category | B1: avg menu cost | C1: avg menu price
A2: entrée | B2: =AVERAGE('Cost Breakdown'!J19,'Cost Breakdown'!J32,'Cost Breakdown'!J45,'Cost Breakdown'!J61,'Cost Breakdown'!J74,'Cost Breakdown'!J95) -> 2.7825 | C2: =AVERAGE('Cost Breakdown'!K19,'Cost Breakdown'!K32,'Cost Breakdown'!K45,'Cost Breakdown'!K61,'Cost Breakdown'!K74,'Cost Breakdown'!K95) -> 8.5833333
A3: side | B3: =AVERAGE('Cost Breakdown'!I107,'Cost Breakdown'!I115,'Cost Breakdown'!I121) -> 0.58666667 | C3: =AVERAGE('Cost Breakdown'!K121,'Cost Breakdown'!K115,'Cost Breakdown'!K107) -> 2
A4: drink | B4: =AVERAGE('Cost Breakdown'!I134,'Cost Breakdown'!I130,'Cost Breakdown'!I127,'Cost Breakdown'!I124) -> 0.83 | C4: =AVERAGE('Cost Breakdown'!K134,'Cost Breakdown'!K130,'Cost Breakdown'!K127,'Cost Breakdown'!K124) -> 4.125
A5: total | B5: =SUM(B2:B4) -> 4.1991667 | C5: =SUM(C2:C4) -> 14.708333
